celltype_classification.py:1037: UserWarning: you are shuffling a 'Series' object which is not a subclass of 'Sequence'; `shuffle` is not guaranteed to behave correctly. E.g., non-numpy array/tensor objects with view semantics may contain duplicates after shuffling.
  Y_train=np.random.shuffle(Y_train)
Traceback (most recent call last):
  File "/home/fazzarello/miniforge3/envs/celltype_classification/lib/python3.8/site-packages/pandas/core/indexes/base.py", line 3653, in get_loc
    return self._engine.get_loc(casted_key)
  File "pandas/_libs/index.pyx", line 147, in pandas._libs.index.IndexEngine.get_loc
  File "pandas/_libs/index.pyx", line 176, in pandas._libs.index.IndexEngine.get_loc
  File "pandas/_libs/hashtable_class_helper.pxi", line 2606, in pandas._libs.hashtable.Int64HashTable.get_item
  File "pandas/_libs/hashtable_class_helper.pxi", line 2630, in pandas._libs.hashtable.Int64HashTable.get_item
KeyError: 322

The above exception was the direct cause of the following exception:

Traceback (most recent call last):
  File "celltype_classification.py", line 1037, in <module>
    Y_train=np.random.shuffle(Y_train)
  File "mtrand.pyx", line 4637, in numpy.random.mtrand.RandomState.shuffle
  File "mtrand.pyx", line 4640, in numpy.random.mtrand.RandomState.shuffle
  File "/home/fazzarello/miniforge3/envs/celltype_classification/lib/python3.8/site-packages/pandas/core/series.py", line 1007, in __getitem__
    return self._get_value(key)
  File "/home/fazzarello/miniforge3/envs/celltype_classification/lib/python3.8/site-packages/pandas/core/series.py", line 1116, in _get_value
    loc = self.index.get_loc(label)
  File "/home/fazzarello/miniforge3/envs/celltype_classification/lib/python3.8/site-packages/pandas/core/indexes/base.py", line 3655, in get_loc
    raise KeyError(key) from err
KeyError: 322
